ERROR — log — 2020-03-21 03:21:46,363 — HTTPSConnectionPool(host='cwiki.apache.org', port=443): Max retries exceeded with url: /confluence/display/WW/Security+Bulletins (Caused by ConnectTimeoutError(<urllib3.connection.VerifiedHTTPSConnection object at 0x7f35a3599860>, 'Connection to cwiki.apache.org timed out. (connect timeout=5)'))
Traceback (most recent call last):
  File "/root/.pyenv/versions/3.6.6/lib/python3.6/site-packages/urllib3/connection.py", line 157, in _new_conn
    (self._dns_host, self.port), self.timeout, **extra_kw
  File "/root/.pyenv/versions/3.6.6/lib/python3.6/site-packages/urllib3/util/connection.py", line 84, in create_connection
    raise err
  File "/root/.pyenv/versions/3.6.6/lib/python3.6/site-packages/urllib3/util/connection.py", line 74, in create_connection
    sock.connect(sa)
socket.timeout: timed out

During handling of the above exception, another exception occurred:

Traceback (most recent call last):
  File "/root/.pyenv/versions/3.6.6/lib/python3.6/site-packages/urllib3/connectionpool.py", line 672, in urlopen
    chunked=chunked,
  File "/root/.pyenv/versions/3.6.6/lib/python3.6/site-packages/urllib3/connectionpool.py", line 376, in _make_request
    self._validate_conn(conn)
  File "/root/.pyenv/versions/3.6.6/lib/python3.6/site-packages/urllib3/connectionpool.py", line 994, in _validate_conn
    conn.connect()
  File "/root/.pyenv/versions/3.6.6/lib/python3.6/site-packages/urllib3/connection.py", line 300, in connect
    conn = self._new_conn()
  File "/root/.pyenv/versions/3.6.6/lib/python3.6/site-packages/urllib3/connection.py", line 164, in _new_conn
    % (self.host, self.timeout),
urllib3.exceptions.ConnectTimeoutError: (<urllib3.connection.VerifiedHTTPSConnection object at 0x7f35a3599860>, 'Connection to cwiki.apache.org timed out. (connect timeout=5)')

During handling of the above exception, another exception occurred:

Traceback (most recent call last):
  File "/root/.pyenv/versions/3.6.6/lib/python3.6/site-packages/requests/adapters.py", line 449, in send
    timeout=timeout
  File "/root/.pyenv/versions/3.6.6/lib/python3.6/site-packages/urllib3/connectionpool.py", line 720, in urlopen
    method, url, error=e, _pool=self, _stacktrace=sys.exc_info()[2]
  File "/root/.pyenv/versions/3.6.6/lib/python3.6/site-packages/urllib3/util/retry.py", line 436, in increment
    raise MaxRetryError(_pool, url, error or ResponseError(cause))
urllib3.exceptions.MaxRetryError: HTTPSConnectionPool(host='cwiki.apache.org', port=443): Max retries exceeded with url: /confluence/display/WW/Security+Bulletins (Caused by ConnectTimeoutError(<urllib3.connection.VerifiedHTTPSConnection object at 0x7f35a3599860>, 'Connection to cwiki.apache.org timed out. (connect timeout=5)'))

During handling of the above exception, another exception occurred:

Traceback (most recent call last):
  File "/home/bug-monitor/struts/init.py", line 15, in struts_latest
    struts = requests.get("https://cwiki.apache.org/confluence/display/WW/Security+Bulletins", timeout=5)
  File "/root/.pyenv/versions/3.6.6/lib/python3.6/site-packages/requests/api.py", line 76, in get
    return request('get', url, params=params, **kwargs)
  File "/root/.pyenv/versions/3.6.6/lib/python3.6/site-packages/requests/api.py", line 61, in request
    return session.request(method=method, url=url, **kwargs)
  File "/root/.pyenv/versions/3.6.6/lib/python3.6/site-packages/requests/sessions.py", line 530, in request
    resp = self.send(prep, **send_kwargs)
  File "/root/.pyenv/versions/3.6.6/lib/python3.6/site-packages/requests/sessions.py", line 643, in send
    r = adapter.send(request, **kwargs)
  File "/root/.pyenv/versions/3.6.6/lib/python3.6/site-packages/requests/adapters.py", line 504, in send
    raise ConnectTimeout(e, request=request)
requests.exceptions.ConnectTimeout: HTTPSConnectionPool(host='cwiki.apache.org', port=443): Max retries exceeded with url: /confluence/display/WW/Security+Bulletins (Caused by ConnectTimeoutError(<urllib3.connection.VerifiedHTTPSConnection object at 0x7f35a3599860>, 'Connection to cwiki.apache.org timed out. (connect timeout=5)'))
ERROR — log — 2020-03-21 04:19:54,208 — HTTPSConnectionPool(host='cwiki.apache.org', port=443): Max retries exceeded with url: /confluence/display/WW/Security+Bulletins (Caused by ConnectTimeoutError(<urllib3.connection.VerifiedHTTPSConnection object at 0x7fc3febb87f0>, 'Connection to cwiki.apache.org timed out. (connect timeout=5)'))
Traceback (most recent call last):
  File "/root/.pyenv/versions/3.6.6/lib/python3.6/site-packages/urllib3/connection.py", line 157, in _new_conn
    (self._dns_host, self.port), self.timeout, **extra_kw
  File "/root/.pyenv/versions/3.6.6/lib/python3.6/site-packages/urllib3/util/connection.py", line 84, in create_connection
    raise err
  File "/root/.pyenv/versions/3.6.6/lib/python3.6/site-packages/urllib3/util/connection.py", line 74, in create_connection
    sock.connect(sa)
socket.timeout: timed out

During handling of the above exception, another exception occurred:

Traceback (most recent call last):
  File "/root/.pyenv/versions/3.6.6/lib/python3.6/site-packages/urllib3/connectionpool.py", line 672, in urlopen
    chunked=chunked,
  File "/root/.pyenv/versions/3.6.6/lib/python3.6/site-packages/urllib3/connectionpool.py", line 376, in _make_request
    self._validate_conn(conn)
  File "/root/.pyenv/versions/3.6.6/lib/python3.6/site-packages/urllib3/connectionpool.py", line 994, in _validate_conn
    conn.connect()
  File "/root/.pyenv/versions/3.6.6/lib/python3.6/site-packages/urllib3/connection.py", line 300, in connect
    conn = self._new_conn()
  File "/root/.pyenv/versions/3.6.6/lib/python3.6/site-packages/urllib3/connection.py", line 164, in _new_conn
    % (self.host, self.timeout),
urllib3.exceptions.ConnectTimeoutError: (<urllib3.connection.VerifiedHTTPSConnection object at 0x7fc3febb87f0>, 'Connection to cwiki.apache.org timed out. (connect timeout=5)')

During handling of the above exception, another exception occurred:

Traceback (most recent call last):
  File "/root/.pyenv/versions/3.6.6/lib/python3.6/site-packages/requests/adapters.py", line 449, in send
    timeout=timeout
  File "/root/.pyenv/versions/3.6.6/lib/python3.6/site-packages/urllib3/connectionpool.py", line 720, in urlopen
    method, url, error=e, _pool=self, _stacktrace=sys.exc_info()[2]
  File "/root/.pyenv/versions/3.6.6/lib/python3.6/site-packages/urllib3/util/retry.py", line 436, in increment
    raise MaxRetryError(_pool, url, error or ResponseError(cause))
urllib3.exceptions.MaxRetryError: HTTPSConnectionPool(host='cwiki.apache.org', port=443): Max retries exceeded with url: /confluence/display/WW/Security+Bulletins (Caused by ConnectTimeoutError(<urllib3.connection.VerifiedHTTPSConnection object at 0x7fc3febb87f0>, 'Connection to cwiki.apache.org timed out. (connect timeout=5)'))

During handling of the above exception, another exception occurred:

Traceback (most recent call last):
  File "/home/bug-monitor/struts/init.py", line 15, in struts_latest
    struts = requests.get("https://cwiki.apache.org/confluence/display/WW/Security+Bulletins", timeout=5)
  File "/root/.pyenv/versions/3.6.6/lib/python3.6/site-packages/requests/api.py", line 76, in get
    return request('get', url, params=params, **kwargs)
  File "/root/.pyenv/versions/3.6.6/lib/python3.6/site-packages/requests/api.py", line 61, in request
    return session.request(method=method, url=url, **kwargs)
  File "/root/.pyenv/versions/3.6.6/lib/python3.6/site-packages/requests/sessions.py", line 530, in request
    resp = self.send(prep, **send_kwargs)
  File "/root/.pyenv/versions/3.6.6/lib/python3.6/site-packages/requests/sessions.py", line 643, in send
    r = adapter.send(request, **kwargs)
  File "/root/.pyenv/versions/3.6.6/lib/python3.6/site-packages/requests/adapters.py", line 504, in send
    raise ConnectTimeout(e, request=request)
requests.exceptions.ConnectTimeout: HTTPSConnectionPool(host='cwiki.apache.org', port=443): Max retries exceeded with url: /confluence/display/WW/Security+Bulletins (Caused by ConnectTimeoutError(<urllib3.connection.VerifiedHTTPSConnection object at 0x7fc3febb87f0>, 'Connection to cwiki.apache.org timed out. (connect timeout=5)'))
